<?xml version="1.0"?>
<robot xmlns:xacro="http://www.ros.org/wiki/xacro" name="bumperbot">

    <xacro:include filename="inertial_macros.xacro"/>
    
    <material name="white">
        <color rgba="1 1 1 1"/>
    </material>

    <material name="orange">
        <color rgba="1 0.3 0.1 1"/>
    </material> 

    <material name="blue">
        <color rgba="0.2 0.2 1 1"/>
    </material>

    <material name="black">
        <color rgba="0 0 0 1"/>
    </material>

    <material name="red">
        <color rgba="1 0 0 1"/>
    </material>

    <!-- BASE LINK -->
    <link name="base_link"></link>

    <!-- BASE FOOTPRINT JOINT -->
    <joint name="base_footprint_joint" type="fixed">
        <parent link="base_footprint"/> 
        <child link="base_link"/>
        <origin xyz="0 0 0" rpy="0 0 0"/>
    </joint>

     <!-- BASE FOOTPRINT LINK -->
     <link name="base_footprint"></link>

    <!-- CHASSIS JOINT -->
    <joint name="chassis_joint" type="fixed">
        <parent link="base_link"/>
        <child link="chassis_link"/>
        <origin xyz="-0.04 0 0"/> <!-- 18/2 = 9 and -5 = 4cm because of dc motor distance and convert to cm to m = 0.04 -->
    </joint>

    <!-- CHASSIS LINK -->
    <link name="chassis_link">
    <visual>
        <origin xyz="0.0 0.0 0.0325" rpy="0.0 0.0 0.0"/>
        <geometry>
            <box size="0.18 0.18 0.065"/>
        </geometry>
        <material name="red"/>
    </visual>

    <collision>
        <origin xyz="0.0 0.0 0.0325" rpy="0.0 0.0 0.0"/>
        <geometry>
            <box size="0.18 0.18 0.065"/>
        </geometry>
    </collision>
    <xacro:inertial_box mass="0.5" x="0.18" y="0.18" z="0.065">
        <origin xyz="0.0 0.0 0.0325" rpy="0.0 0.0 0.0"/>
    </xacro:inertial_box>
    </link>

    <gazebo reference="chassis_link">
        <material>Gazebo/Red</material>
    </gazebo>

    <!-- LEFT WHEEL JOINT -->
    <joint name="wheel_left_joint" type="continuous">
        <origin xyz="0.0 0.105 0.0" rpy="-${pi/2} 0.0 0.0"/>
        <parent link="base_link"/>
        <child link="left_wheel_link"/>
        <axis xyz="0.0 0.0 1.0"/>
    </joint>
    
    <!-- LEFT WHEEL LINK -->
    <link name="left_wheel_link">
        <visual>
            <geometry>
                <cylinder radius="0.03405" length="0.027"/>
                <!-- <cylinder radius="0.03405" length="0.01"/> -->
            </geometry>
            <material name="white"/>
        </visual>

        <collision>
            <geometry>
                <cylinder radius="0.03405" length="0.027"/>
                <!-- <sphere radius="0.0325"/> -->
            </geometry>
        </collision>
        <xacro:inertial_cylinder mass="0.05" length="0.027" radius="0.03405">
            <origin xyz="0.0 0.0 0.0" rpy="0.0 0.0 0.0"/>
        </xacro:inertial_cylinder>
    </link>

    <gazebo reference="left_wheel_link">
        <material>Gazebo/White</material>
    </gazebo>

    <!-- RIGHT WHEEL JOINT -->
    <joint name="wheel_right_joint" type="continuous">
        <origin xyz="0.0 -0.105 0.0" rpy="${pi/2} 0.0 0.0"/>
        <parent link="base_link"/>
        <child link="right_wheel_link"/>
        <axis xyz="0.0 0.0 -1.0"/>
    </joint>

    <!-- RIGHT WHEEL LINK -->
    <link name="right_wheel_link">
    <visual>
        <geometry>
            <cylinder radius="0.03405" length="0.027"/>
            <!-- <cylinder radius="0.03405" length="0.01"/> -->
        </geometry>
        <material name="white"/>
    </visual>

    <collision>
        <geometry>
            <cylinder radius="0.03405" length="0.027"/>
            <!-- <sphere radius="0.0325"/> -->
        </geometry>
    </collision>
    <xacro:inertial_cylinder mass="0.05" length="0.027" radius="0.03405">
        <origin xyz="0.0 0.0 0.0" rpy="0.0 0.0 0.0"/>
    </xacro:inertial_cylinder>
    </link>

    <gazebo reference="right_wheel_link">
        <material>Gazebo/White</material>
    </gazebo>

    <!-- CAMERA JOINT -->
    <joint name="camera_joint" type="fixed">
        <origin xyz="0.065 0.0 0.105" rpy="0.0 0.0 0.0"/>
        <parent link="chassis_link"/>
        <child link="camera_link"/>
    </joint>

    <!-- CAMERA LINK -->
    <link name="camera_link">
        <visual>
            <origin xyz="0.0 0.0 0.0" rpy="0.0 0.0 0.0"/>
            <geometry>
                <box size="0.014 0.04 0.08"/>
            </geometry>
            <material name="blue"/>
        </visual>

        <collision>
            <geometry>
                <box size="0.014 0.04 0.08"/>
            </geometry>
        </collision>
        <xacro:inertial_box mass="0.01" x="0.014" y="0.04" z="0.08">
            <origin xyz="0.0 0.0 0.0" rpy="0.0 0.0 0.0"/>
        </xacro:inertial_box>
    </link>

    <gazebo reference="camera_link">
        <material>Gazebo/Black</material>
    </gazebo>

    <joint name="camera_optical_joint" type="fixed">
        <parent link="camera_link"/>
        <child link="camera_link_optical"/>
        <origin xyz="0 0 0" rpy="${-pi/2} 0 ${-pi/2}"/>
    </joint>

    <link name="camera_link_optical"></link>

    <!-- LIDAR CASE JOINT -->
    <joint name="lidar_joint" type="fixed">
        <parent link="chassis_link"/>
        <child link="ldlidar_base"/>
        <origin xyz="0.0 0.0 0.1" rpy="0.0 0.0 0.0"/>
    </joint>
    
    <!-- LIDAR CASE LINK -->
    <link name="ldlidar_base">
    <visual>
        <geometry>
            <box size="0.08 0.18 0.095"/>
        </geometry>
        <material name="red"/>
    </visual>

    <collision>
        <geometry>
            <box size="0.08 0.18 0.095"/>
        </geometry>
    </collision>
    <xacro:inertial_box mass="0.03" x="0.08" y="0.18" z="0.095">
        <origin xyz="0.0 0.0 0.0" rpy="0.0 0.0 0.0"/>
    </xacro:inertial_box>
    </link>

    <gazebo reference="ldlidar_base">
        <material>Gazebo/Red</material>
    </gazebo>

    <!-- LIDAR  JOINT -->
    <joint name="lidar_case_joint" type="fixed">
        <origin xyz="0.0 0.0 0.055 " rpy="0.0 0.0 0.0"/>
        <parent link="ldlidar_base"/>
        <child link="ldlidar_link"/>
    </joint>
    
    <!-- LIDAR LINK -->
    <link name="ldlidar_link">
    <visual>
        <!-- <origin xyz="0.0 0.0 0.0" rpy="0.0 0.0 0.0"/> -->
        <geometry>
            <cylinder radius="0.0175" length="0.0175"/>
        </geometry>
        <material name="blue"/>
    </visual>

    <collision>
        <geometry>
            <cylinder radius="0.0175" length="0.0175"/>
        </geometry>
    </collision>
    <xacro:inertial_cylinder mass="0.1" length="0.0175" radius="0.0175">
        <origin xyz="0.0 0.0 0.0" rpy="0.0 0.0 0.0"/>
    </xacro:inertial_cylinder>
    </link>

    <gazebo reference="ldlidar_link">
        <material>Gazebo/Blue</material>
    </gazebo>

    <!-- IMU JOINT -->
    <joint name="imu_joint" type="fixed">
        <origin xyz="0.0 0.0 0.015 " rpy="0.0 0.0 0.0"/>
        <parent link="ldlidar_link"/>
        <child link="imu_link"/>
    </joint>

    <!-- IMU LINK -->
    <link name="imu_link">
    <visual>
        <geometry>
            <cylinder radius="0.01" length="0.01"/>
        </geometry>
        <material name="white"/>
    </visual>

    <collision>
        <geometry>
            <cylinder radius="0.01" length="0.01"/>
        </geometry>
    </collision>
    <xacro:inertial_cylinder mass="0.1" length="0.01" radius="0.01">
        <origin xyz="0.0 0.0 0.0" rpy="0.0 0.0 0.0"/>
    </xacro:inertial_cylinder>
    </link>

    <gazebo reference="imu_link">
        <material>Gazebo/White</material>
    </gazebo>

    <!-- CASTER HOLDER JOINT -->
    <joint name="caster_holder_joint" type="fixed">
        <origin xyz="-0.06 0.0 0.0" rpy="0.0 0.0 0.0"/>
        <parent link="chassis_link"/>
        <child link="caster_holder_link"/>
    </joint>

    <!-- CASTER HOLDER LINK -->
    <link name="caster_holder_link">
        <visual>
            <origin xyz="0.0 0.0 0.0" rpy="0.0 0.0 0.0"/>
            <geometry>
                <cylinder radius="0.0175" length="0.040"/>
            </geometry>
            <material name="white"/>
        </visual>
    
        <collision>
            <geometry>
                <cylinder radius="0.0175" length="0.040"/>
            </geometry>
        </collision>

        <xacro:inertial_cylinder mass="0.01" length="0.040" radius="0.0175">
        <origin xyz="0.0 0.0 0.0" rpy="0.0 0.0 0.0"/>
        </xacro:inertial_cylinder>
    </link>

    <gazebo reference="caster_holder_link">
        <material>Gazebo/White</material>
    </gazebo>

    <!-- CASTER BALL JOINT -->
    <joint name="caster_ball_joint" type="fixed">
        <origin xyz="0.0 0.0 -0.020" rpy="0.0 0.0 0.0"/>
        <parent link="caster_holder_link"/>
        <child link="caster_link"/>
    </joint>
    
    <!-- CASTER BALL LINK -->
    <link name="caster_link">
    <visual>
        <origin xyz="0.0 0.0 0.0" rpy="0.0 0.0 0.0"/>
        <geometry>
            <sphere radius="0.0125"/>
        </geometry>
        <material name="white"/>
    </visual>

    <collision>
        <geometry>
            <sphere radius="0.0125"/>
        </geometry>
    </collision>
    <xacro:inertial_sphere mass="0.01" radius="0.0125">
        <origin xyz="0.0 0.0 0.0" rpy="0.0 0.0 0.0"/>
    </xacro:inertial_sphere>
    </link>

    <gazebo reference="caster_link">
        <material>Gazebo/White</material>
        <mu1 value="0.001"/>
        <mu2 value="0.001"/>
    </gazebo>

    <!-- GAZEBO Lidar Plugin -->
    <gazebo reference="ldlidar_link">
        <sensor name="laser" type="ray">
            <pose> 0 0 0 0 0 0 </pose>
            <visualize>true</visualize>
            <update_rate>10</update_rate>
            <ray>
                <scan>
                    <horizontal>
                    <samples>360</samples>
                    <!-- <resolution>1</resolution> -->
                    <!-- <min_angle>0.00</min_angle> -->
                    
                    <min_angle>-3.14</min_angle>
                    <max_angle>3.14</max_angle>

                    <!-- <min_angle>0.00</min_angle>
                    <max_angle>3.14</max_angle>  -->

                    <!-- <max_angle>6.28319</max_angle>  -->

                    <!-- 3.14 is 180 degree -->
                  </horizontal>
                </scan>
                <range>
                    <min>0.3</min>
                    <max>12</max> 
                    <!-- <min>0.120</min>
                    <max>3.5</max> -->
                    <!-- <resolution>0.015</resolution> -->
                </range>
            </ray>
            <plugin name="laser_controller" filename="libgazebo_ros_ray_sensor.so">
            <ros>
                <remapping>~/out:=scan</remapping>
                <!-- <argument>~/out:=scan</argument> -->
            </ros>
            <output_type>sensor_msgs/LaserScan</output_type>
            <frame_name>ldlidar_link</frame_name>
            </plugin>
        </sensor>
    </gazebo>

    <!-- CAMERA  Plugin -->
    <gazebo reference="camera_link">
        <sensor type="camera" name="camera">
        <pose>0 0 0 0 0 0</pose>
        <visualize>true</visualize>
        <update_rate>10.0</update_rate>
        <camera name="head">
            <horizontal_fov>1.089</horizontal_fov>
            <image>
                <width>640</width>
                <height>480</height>
                <format>R8G8B8</format>
            </image>
            <clip>
                <near>0.05</near>
                <far>8.0</far>
            </clip>
        </camera>
        <!-- <plugin name="camera_controller" filename="libgazebo_ros_camera.so">
            <alwaysOn>true</alwaysOn>
            <updateRate>0.0</updateRate>
            <imageTopicName>image_raw</imageTopicName>
            <cameraInfoTopicName>camera_info</cameraInfoTopicName>
            <frameName>camera_link_optical</frameName>
            <hackBaseline>0.07</hackBaseline>
            <distortionK1>0.0</distortionK1>
            <distortionK2>0.0</distortionK2>
            <distortionK3>0.0</distortionK3>
            <distortionT1>0.0</distortionT1>
            <distortionT2>0.0</distortionT2>
        </plugin> -->

        <plugin name="camera_controller" filename="libgazebo_ros_camera.so">
            <frame_name>camera_link_optical</frame_name>
        </plugin>
        </sensor>
    </gazebo>

    <!-- IMU -->
    <!--Refer to this link https://docs.ros.org/en/rolling/p/gazebo_plugins/generated/classgazebo__plugins_1_1GazeboRosImuSensor.html#class-documentation -->
    <gazebo reference="imu_link">
        <sensor name="imu_sensor" type="imu">
            <plugin filename="libgazebo_ros_imu_sensor.so" name="imu_plugin">
               <ros>
                 <namespace>/imu</namespace>
                 <remapping>~/out:=out</remapping>
               </ros>
               <initial_orientation_as_reference>false</initial_orientation_as_reference>
             </plugin>
             <always_on>true</always_on>
             <update_rate>100</update_rate>
             <visualize>true</visualize>
             <imu>
               <angular_velocity>
                 <x>
                   <noise type="gaussian">
                     <mean>0.0</mean>
                     <stddev>2e-4</stddev>
                     <bias_mean>0.0000075</bias_mean>
                     <bias_stddev>0.0000008</bias_stddev>
                   </noise>
                 </x>
                 <y>
                   <noise type="gaussian">
                     <mean>0.0</mean>
                     <stddev>2e-4</stddev>
                     <bias_mean>0.0000075</bias_mean>
                     <bias_stddev>0.0000008</bias_stddev>
                   </noise>
                 </y>
                 <z>
                   <noise type="gaussian">
                     <mean>0.0</mean>
                     <stddev>2e-4</stddev>
                     <bias_mean>0.0000075</bias_mean>
                     <bias_stddev>0.0000008</bias_stddev>
                   </noise>
                 </z>
               </angular_velocity>
               <linear_acceleration>
                 <x>
                   <noise type="gaussian">
                     <mean>0.0</mean>
                     <stddev>1.7e-2</stddev>
                     <bias_mean>0.1</bias_mean>
                     <bias_stddev>0.001</bias_stddev>
                   </noise>
                 </x>
                 <y>
                   <noise type="gaussian">
                     <mean>0.0</mean>
                     <stddev>1.7e-2</stddev>
                     <bias_mean>0.1</bias_mean>
                     <bias_stddev>0.001</bias_stddev>
                   </noise>
                 </y>
                 <z>
                   <noise type="gaussian">
                     <mean>0.0</mean>
                     <stddev>1.7e-2</stddev>
                     <bias_mean>0.1</bias_mean>
                     <bias_stddev>0.001</bias_stddev>
                   </noise>
                 </z>
               </linear_acceleration>
             </imu>
           </sensor>
        
        <!--1st Imu Option-->
        <!-- <sensor name="imu_sensor" type="imu">
        <always_on>true</always_on>
        <update_rate>100</update_rate>
        <plugin name="imu_plugin" filename="libgazebo_ros_imu_sensor.so">
            <ros>
            <namespace>/imu</namespace>
            <remapping>~/out:=out</remapping>
            </ros>
        </plugin>
        </sensor> -->

        <!-- <gravity>true</gravity>
        <sensor name="imu_sensor" type="imu">
          <always_on>true</always_on>
          <update_rate>100</update_rate>
          <visualize>true</visualize>
          <topic>__default_topic__</topic>
          <plugin filename="libgazebo_ros_imu_sensor.so" name="imu_plugin">
            <ros>
                <namespace>/imu</namespace>
                <remapping>~/out:=out</remapping>
                </ros>
            <topicName>imu</topicName>
            <bodyName>imu_link</bodyName>
            <updateRateHZ>10.0</updateRateHZ>
            <gaussianNoise>0.0</gaussianNoise>
            <xyzOffset>0 0 0</xyzOffset>
            <rpyOffset>0 0 0</rpyOffset>
            <frameName>imu_link</frameName>
            <initialOrientationAsReference>false</initialOrientationAsReference>
          </plugin>
          <pose>0 0 0 0 0 0</pose>
        </sensor> -->

        <!-- <sensor name="imu_sensor" type="imu">
            <always_on>true</always_on>
            <update_rate>30</update_rate>
            <plugin filename="libgazebo_ros_imu_sensor.so" name="imu_plugin">
                <ros>
                <namespace>/imu</namespace>
                <remapping>~/out:=out</remapping>
              </ros>
            </plugin>
          </sensor> -->

        <!--2nd Imu Option-->
        <!-- <sensor name="imu_sensor" type="imu">
            <always_on>true</always_on>
            <update_rate>100</update_rate>

            <plugin name="my_imu_plugin" filename="libgazebo_ros_imu_sensor.so">
                <ros>
                    <namespace>/imu</namespace>
                    <remapping>~/out:=out</remapping>
                </ros>
                <imu>
                <angular_velocity>
                    <x>
                    <noise type="gaussian">
                        <mean>0.0</mean>
                        <stddev>2e-4</stddev>
                    </noise>
                    </x>
                    <y>
                    <noise type="gaussian">
                        <mean>0.0</mean>
                        <stddev>2e-4</stddev>
                    </noise>
                    </y>
                    <z>
                    <noise type="gaussian">
                        <mean>0.0</mean>
                        <stddev>2e-4</stddev>
                    </noise>
                    </z>
                </angular_velocity>
                <linear_acceleration>
                    <x>
                    <noise type="gaussian">
                        <mean>0.0</mean>
                        <stddev>1.7e-2</stddev>
                    </noise>
                    </x>
                    <y>
                    <noise type="gaussian">
                        <mean>0.0</mean>
                        <stddev>1.7e-2</stddev>
                    </noise>
                    </y>
                    <z>
                    <noise type="gaussian">
                        <mean>0.0</mean>
                        <stddev>1.7e-2</stddev>
                    </noise>
                    </z>
                </linear_acceleration>
                </imu>
        </plugin>
        </sensor> -->
      </gazebo>
</robot>
